Workbook

Sheet DASHBOARD
B1: Performance Dashboard
B2: Client Name: ATC
B4: Last updated: 2/5/2026
B13: 6 Rs
B16: Success Factor | C16: Measurement | D16: 2019 | E16: 2022 | F16: 2023 | G16: 2024 | H16: Historic Average | I16: 2026 Actual | J16: 2026 Goal | K16: 2026 Percent to Goal | L16: Goal
B17: Reach​ | C17: Total Attendees | D17: 4077 | E17: 3927 | F17: 5019 | H17: =AVERAGE(D17:G17) -> 4341 | K17: =I17/J17 -> #DIV/0! | L17: 1
C18: Paid Attendees | F18: 3634 | H18: =AVERAGE(D18:G18) -> 3634 | K18: =I18/J18 -> #DIV/0! | L18: 1
B19: Retention​ | C19: +40% Returning Attendees | D19: . | E19: . | F19: 0.37 | H19: =AVERAGE(D19:G19) -> 0.37 | K19: =I19/J19 -> #DIV/0! | L19: 1
B20: Relevance​ | C20: +20% of Addressable Audience | D20: . | E20: . | F20: 0.16 | H20: =AVERAGE(D20:G20) -> 0.16 | K20: =I20/J20 -> #DIV/0! | L20: 1
B21: Reputation​ | C21: NPS of 60+ | D21: . | E21: . | F21: . | H21: =AVERAGE(D21:G21) -> #DIV/0! | K21: =I21/J21 -> #DIV/0! | L21: 1
B22: Revenue​ | C22: Gross Revenue | D22: 4887599 | E22: 4881907 | F22: 4844787 | H22: =AVERAGE(D22:G22) -> 4871431 | K22: =I22/J22 -> #DIV/0! | L22: 1
B23: ROI​ | C23: Net Profit* | D23: 2074035 | E23: 1332966 | F23: 1565737 | H23: =AVERAGE(D23:G23) -> 1657579.3 | K23: =I23/J23 -> #DIV/0! | L23: 1
C24: +20% Margin | D24: 0.42 | E24: 0.27 | F24: 0.32 | H24: =AVERAGE(D24:G24) -> 0.33666667 | K24: =I24/J24 -> #DIV/0! | L24: 1
B31: Event Registrations
B70: Email
B109: Organic Social
B143: Paid Media
B148: Date Range: xxxx (Totals / Averages)
B150: LinkedIn | G150: Meta | V150: Google Search | AA150: Google Display
B152: Impressions | C152: Clicks | D152: Cost | E152: CPC | G152: Impressions | H152: Clicks | I152: Cost | J152: CPC | V152: Impressions | W152: Clicks | X152: Cost | Y152: CPC | AA152: Impressions | AB152: Clicks | AC152: Cost | AD152: CPC
B153: ='Paid Media'!B34 -> 111528 | C153: ='Paid Media'!C34 -> 1096 | D153: ='Paid Media'!D34 -> 1136.35 | E153: ='Paid Media'!E34 -> 1.0368157 | G153: ='Paid Media'!J34 -> 510884 | H153: ='Paid Media'!K34 -> 4007 | I153: ='Paid Media'!L34 -> 5264.58 | J153: ='Paid Media'!M34 -> 1.3138458 | V153: ='Paid Media'!R34 -> 55823 | W153: ='Paid Media'!S34 -> 993 | X153: ='Paid Media'!T34 -> 3905.06 | Y153: ='Paid Media'!U34 -> 3.9325881 | AA153: ='Paid Media'!Z34 -> 498415 | AB153: ='Paid Media'!AA34 -> 555 | AC153: ='Paid Media'!AB34 -> 1658.88 | AD153: ='Paid Media'!AC34 -> 2.988973
V154: 6
B155: CTR | C155: Conversions | D155: Conversion Rate | E155: CPA | G155: CTR | H155: Conversions | I155: Conversion Rate | J155: CPA | V155: CTR | W155: Conversions | X155: Conversion Rate | Y155: CPA | AA155: CTR | AB155: Conversions | AC155: Conversion Rate | AD155: CPA
B156: ='Paid Media'!F34 -> 0.0098271286 | C156: ='Paid Media'!G34 -> 0 | D156: ='Paid Media'!H34 -> 0 | E156: ='Paid Media'!I34 -> #DIV/0! | G156: ='Paid Media'!N34 -> 0.0078432677 | H156: ='Paid Media'!O34 -> 5 | I156: ='Paid Media'!P34 -> 0.0012478163 | J156: ='Paid Media'!Q34 -> 1052.916 | V156: ='Paid Media'!V34 -> 0.017788367 | W156: ='Paid Media'!X34 -> 0.71237664 | X156: ='Paid Media'!X34 -> 0.71237664 | Y156: ='Paid Media'!Y34 -> 5.5203777 | AA156: ='Paid Media'!AD34 -> 0.0011135299 | AB156: ='Paid Media'!AE34 -> 0 | AC156: ='Paid Media'!AF34 -> 0 | AD156: ='Paid Media'!AG34 -> #DIV/0!
B159: Total Campaigns | C159: Total Budget | D159: Total Spent | E159: LI Total Remaining | G159: Total Campaigns | H159: Total Budget | I159: Total Spent | J159: FB Total Remaining | V159: Total Campaigns | W159: Total Budget | X159: Total Spent | Y159: X Total Remaining | AA159: Total Campaigns | AB159: Total Budget | AC159: Total Spent | AD159: X Total Remaining
AA160: 5 | AB160: 10000 | AC160: 5000 | AD160: =AB160-AC160 -> 5000

Sheet MARKETING DATA -->

Sheet Emails
A1: ATC
A2: Email Name | B2: Audience (List) | C2: Deployment Date | D2: Deployment Day of Week | E2: Deployment Time of Day | F2: Total Emails Sent | G2: Open Rate | H2: Open Rate (Benchmark) | I2: Click-Through Rate (clicks / devilieries) | J2: CTR (Benchmark) | K2: Click-To-Open Rate | L2: CTO (Benchmark) | M2: Delivery Rate | N2: Delivery Rate (Benchmark) | O2: Unsubscribe % | P2: Unsubscribe % (Benchmark) | Q2: Subject Line | R2: Notes | S2: Footer
A3: Call for Proposals Email #1 (All Prospects) | B3: All Prospects | C3: 45821 | D3: Friday | E3: 0.54166667 | F3: 21125 | G3: 0.409 | H3: 0.15 | I3: =463/17430 -> 0.026563396 | J3: 0.03 | K3: =463/7135 -> 0.064891381 | L3: 0.06 | M3: =17430/21125 -> 0.82508876 | N3: 0.95 | O3: =10/17430 -> 0.00057372347 | P3: 0.0025 | Q3: {NOW OPEN} ATC 2026 Call for Programs
A4: Call for Proposals Email #2 (All Prospects) | B4: All Prospects | C4: 45828 | D4: Friday | E4: 0.58888889 | F4: 21109 | G4: 0.576 | H4: 0.15 | I4: =4064/17327 -> 0.23454724 | J4: 0.03 | K4: =4064/9980 -> 0.40721443 | L4: 0.06 | M4: =17327/21109 -> 0.82083472 | N4: 0.95 | O4: =10/17327 -> 0.00057713395 | P4: 0.0025 | Q4: Your Voice. Your Ideas. Your Congress.
A5: Call for Proposals Email #3 (All Prospects) | B5: All Prospects | C5: 45834 | D5: Thursday | E5: 0.61458333 | F5: 21091 | G5: 0.49 | H5: 0.15 | I5: 0.093 | J5: 0.03 | K5: =1627/8578 -> 0.18967125 | L5: 0.06 | M5: =17501/21091 -> 0.82978522 | N5: 0.95 | O5: =12/17501 -> 0.0006856751 | P5: 0.0025 | Q5: Tips to Strengthen Your ATC 2026 Session Proposal
A6: Call for Proposals Email #4a (Past Submitters) | B6: Past Submitters | C6: 45847 | D6: Wednesday | E6: 0.70833333 | F6: 190 | G6: 0.705 | H6: 0.15 | I6: =28/176 -> 0.15909091 | J6: 0.03 | K6: =28/124 -> 0.22580645 | L6: 0.06 | M6: =176/190 -> 0.92631579 | N6: 0.95 | O6: 0 | P6: 0.0025 | Q6: You're Invited Back: Call for 2026 Proposals
A7: Call for Proposals Email #4b (All Prospects) | B7: All Prospects | C7: 45847 | D7: Wednesday | E7: 0.70833333 | F7: 20866 | G7: 0.443 | H7: 0.15 | I7: 0.09 | J7: 0.03 | K7: =1530/7552 -> 0.20259534 | L7: 0.06 | M7: =17044/20866 -> 0.81683121 | N7: 0.95 | O7: =8/17044 -> 0.00046937339 | P7: 0.0025 | Q7: Be Heard at ATC 2026: Submit Your Idea
A8: Call for Proposals Email #5 (All Prospects) | B8: All Prospects | C8: 45855 | D8: Thursday | E8: 0.45833333 | F8: 21041 | G8: 0.415 | H8: 0.15 | I8: =1112/17315 -> 0.064221773 | J8: 0.03 | K8: =1112/7178 -> 0.1549178 | L8: 0.06 | M8: =17315/21041 -> 0.82291716 | N8: 0.95 | O8: =7/17315 -> 0.00040427375 | P8: 0.0025 | Q8: Final Weeks! Submit Your Proposal for ATC 2026
A9: INTL Email #1 - Survey (International Attendees) | B9: International Attendees | C9: 45861 | D9: Wednesday | E9: 0.35416667 | F9: 2824 | G9: 0.511 | H9: 0.15 | I9: 0.086 | J9: 0.03 | K9: =195/1145 -> 0.17030568 | L9: 0.06 | M9: =2521/2824 -> 0.89270538 | N9: 0.95 | O9: =1/2521 -> 0.00039666799 | P9: 0.0025 | Q9: Your Input Is Needed
A10: Call for Proposals Email #6 (All Prospects) | B10: All Prospects | C10: 45860 | D10: Tuesday | E10: 0.58333333 | F10: 21026 | G10: 0.512 | H10: 0.15 | I10: 0.017 | J10: 0.03 | K10: =273/7750 -> 0.035225806 | L10: 0.06 | M10: =17193/21026 -> 0.81770189 | N10: 0.95 | O10: =12/17193 -> 0.00069795847 | P10: 0.0025 | Q10: Your Perspective Matters: Submit Your ATC 2026 Proposal
A11: Call for Proposals Email #7 (All Prospects) | B11: All Prospects | C11: 45876 | D11: Thursday | E11: 0.70833333 | F11: 21002 | G11: 0.46 | H11: 0.15 | I11: =374/17126 -> 0.021838141 | J11: 0.03 | K11: =374/7875 -> 0.047492063 | L11: 0.06 | M11: =17126/21002 -> 0.81544615 | N11: 0.95 | O11: =6/17126 -> 0.00035034451 | P11: 0.0025 | Q11: Deadline Approaching: Final Week to Submit for ATC 2026
A12: Call for Proposals Email #8 (All Prospects) | B12: All Prospects | C12: 45881 | D12: Tuesday | E12: 0.46388889 | F12: 20993 | G12: 0.443 | H12: 0.15 | I12: =245/17103 -> 0.014324972 | J12: 0.03 | K12: =245/7577 -> 0.032334697 | L12: 0.06 | M12: =17103/20993 -> 0.81470014 | N12: 0.95 | O12: =11/17103 -> 0.00064316202 | P12: 0.0025 | Q12: 48 Hours Left
A13: Call for Proposals & State-of-the-Art Speakers Email #9.5 Deadline Extended (All Prospects) | B13: All Prospects | C13: 45883 | D13: Thursday | E13: 0.70833333 | F13: 33567 | G13: 0.43 | H13: 0.15 | I13: 0.012 | J13: 0.03 | K13: =350/12269 -> 0.028527182 | L13: 0.06 | M13: =28520/33567 -> 0.849644 | N13: 0.95 | O13: =27/28520 -> 0.00094670407 | P13: 0.0025 | Q13: Deadline Extended for ATC 2026 Proposals
A14: Call for Abstracts Email #10 (All Prospects) | B14: All Prospects | C14: 45887 | D14: Monday | E14: 0.54166667 | F14: 19571 | G14: 0.443 | H14: 0.15 | I14: =222/17937 -> 0.012376652 | J14: 0.03 | K14: =222/7940 -> 0.027959698 | L14: 0.06 | M14: =17937/19571 -> 0.91650912 | N14: 0.95 | O14: =3/17937 -> 0.00016725205 | P14: 0.0025 | Q14: Now Open: ATC 2026 Abstract Submissions
A15: Email #9 - Call for Proposals - 24 Hours Left 8/21 (All Prospects) | B15: All Prospects | C15: 45890 | D15: Thursday | E15: 0.48125 | F15: 19570 | G15: 0.42 | H15: 0.15 | I15: =1354/17859 -> 0.075816115 | J15: 0.03 | K15: =1354/7508 -> 0.18034097 | L15: 0.06 | M15: =17859/19570 -> 0.91257026 | N15: 0.95 | O15: =11/17859 -> 0.00061593594 | P15: 0.0025 | Q15: Ends Tonight: Your Last Chance to Submit
A16: Call for Abstracts Email #10.5 | B16: Past Abstract Submitters & Past Attendees: ATC2026 | C16: 45904 | D16: Thursday | E16: 0.45833333 | F16: 5851 | G16: 0.095 | H16: 0.15 | I16: =499/5227 -> 0.09546585 | J16: 0.03 | K16: =499/499 -> 1 | L16: 0.06 | M16: =5227/5851 -> 0.89335156 | N16: 0.95 | O16: =3/5227 -> 0.00057394299 | P16: 0.0025 | Q16: ATC 2026 Abstracts Deadline Is November 13
A17: Awareness Email #1 Save the Date | B17: WTC Attendees | C17: 45908 | D17: Monday | E17: 0.70833333 | F17: 6180 | G17: 0.016 | H17: 0.15 | I17: =95/5939 -> 0.015995959 | J17: 0.03 | K17: 1 | L17: 0.06 | M17: =5939/6180 -> 0.96100324 | N17: 0.95 | O17: =15/5939 -> 0.0025256777 | P17: 0.0025 | Q17: Learning Doesn't Have An Expiration Date
A18: Awareness Email #2 Save the Date | B18: All Prospects excluding WTC Attendees | C18: 45908 | D18: Monday | E18: 0.70833333 | F18: 16868 | G18: 0.01 | H18: 0.15 | I18: 0.01 | J18: 0.03 | K18: 1 | L18: 0.06 | M18: =15099/16868 -> 0.89512687 | N18: 0.95 | O18: =5/15099 -> 0.00033114776 | P18: 0.0025 | Q18: Is Boston in Your Budget Yet?
A19: Call for Abstracts Email #11a | B19: All Prospects (11a Half) | C19: 45911 | D19: Thursday | E19: 0.58333333 | F19: 10089 | G19: 0.433 | H19: 0.15 | I19: 0.005 | J19: 0.03 | K19: =48/3998 -> 0.012006003 | L19: 0.06 | M19: =9227/10089 -> 0.91456041 | N19: 0.95 | O19: =4/9227 -> 0.00043351035 | P19: 0.0025 | Q19: Have You Submitted Your ATC 2026 Abstract?
A20: Call For Abstracts Email #11b | B20: All Prospects (11b Half) | C20: 45911 | D20: Thursday | E20: 0.58333333 | F20: 10087 | G20: 0.44 | H20: 0.15 | I20: =73/9201 -> 0.0079339202 | J20: 0.03 | K20: =73/4046 -> 0.018042511 | L20: 0.06 | M20: =9201/10087 -> 0.91216417 | N20: 0.95 | O20: =2/9201 -> 0.00021736768 | P20: 0.0025 | Q20: Have You Submitted Your ATC 2026 Abstract?
A21: Call for Abstracts Email #12a Visa Focus (International) | B21: International Attendees | C21: 45924 | D21: Wednesday | E21: 0.35416667 | F21: 2711 | G21: 0.467 | H21: 0.15 | I21: 0.027 | J21: 0.03 | K21: =71/1241 -> 0.057211926 | L21: 0.06 | M21: =2655/2711 -> 0.97934342 | N21: 0.95 | O21: =2/2655 -> 0.00075329567 | P21: 0.0025 | Q21: Important - Abstract Submissions for ATC 2026
A22: Call for Abstracts Email #12b | B22: 2026 Attendee House Marketing List (excluding unsubs & undeliverable & INTL) | C22: 45930 | D22: Tuesday | E22: 0.70833333 | F22: 16156 | G22: 0.42 | H22: 0.15 | I22: 0.0009 | J22: 0.03 | K22: =146/6578 -> 0.022195196 | L22: 0.06 | M22: =15671/16156 -> 0.96998019 | N22: 0.95 | O22: =8/15671 -> 0.0005104971 | P22: 0.0025 | Q22: Be Part of the Breakthroughs at ATC 2026
A23: Call for Abstracts Email #13 | B23: 2026 Attendee House Marketing List (excluding unsubs & undeliverable & INTL) | C23: 45938 | D23: Wednesday | E23: 0.58333333 | F23: 18863 | G23: 0.43 | H23: 0.15 | I23: 0.091 | J23: 0.03 | K23: =1668/7843 -> 0.21267372 | L23: 0.06 | M23: =18245/18863 -> 0.96723745 | N23: 0.95 | O23: =4/18245 -> 0.00021923815 | P23: 0.0025 | Q23: Keep This In Mind Before Hitting Submit
A24: Awareness Email #3 Save the Date | B24: 2026 Attendee House Marketing List (excluding unsubs & undeliverable) | C24: 45946 | D24: Thursday | E24: 0.45833333 | F24: 18868 | G24: 0.455 | H24: 0.15 | I24: =2113/18248 -> 0.11579351 | J24: 0.03 | K24: =2113/8304 -> 0.25445568 | L24: 0.06 | M24: =18248/18868 -> 0.96714013 | N24: 0.95 | O24: =3/18248 -> 0.00016440158 | P24: 0.0025 | Q24: ATC 2026 is Close to Home!
A25: Call for Abstracts Email #14 | B25: 2026 Attendee House Marketing List (excluding unsubs & undeliverable) | C25: 45953 | D25: Thursday | E25: 0.70833333 | F25: 18871 | G25: 0.524 | H25: 0.15 | I25: =189/18217 -> 0.010374925 | J25: 0.03 | K25: =189/9452 -> 0.019995768 | L25: 0.06 | M25: =18217/18871 -> 0.96534365 | N25: 0.95 | O25: =3/18217 -> 0.00016468134 | P25: 0.0025 | Q25: ATC 2026: Where Ambition Shapes the Future
A26: Call for Abstracts Email #15 | B26: 2026 Attendee House Marketing List (excluding unsubs & undeliverable) | C26: 45959 | D26: Wednesday | E26: 0.45833333 | F26: 19067 | G26: 0.365 | H26: 0.15 | I26: =169/18393 -> 0.0091882781 | J26: 0.03 | K26: =169/6719 -> 0.025152552 | L26: 0.06 | M26: =18393/19067 -> 0.96465097 | N26: 0.95 | O26: =8/18393 -> 0.00043494808 | P26: 0.0025 | Q26: Get Published in the American Journal of Transplantation
A27: Call for Abstracts Email #16 | B27: 2026 Attendee House Marketing List (excluding unsub & undeliverable & INTL "no" | C27: 45967 | D27: Thursday | E27: 0.58333333 | F27: 18922 | G27: 0.458 | H27: 0.15 | I27: 0.013 | J27: 0.03 | K27: =244/8397 -> 0.029057997 | L27: 0.06 | M27: =18322/18992 -> 0.96472199 | N27: 0.95 | O27: =7/18322 -> 0.00038205436 | P27: 0.0025 | Q27: Submit your abstract before the Nov. 13 deadline and advance the science of transplantation
A28: Call for Abstracts Email #17 | B28: 2026 Attendee House Marketing List (excluding unsub & undeliverable & INTL "no") | C28: 45972 | D28: Tuesday | E28: 0.45833333 | F28: 18989 | G28: 0.036 | H28: 0.15 | I28: 0.014 | J28: 0.03 | K28: =261/663 -> 0.39366516 | L28: 0.06 | M28: =18282/18989 -> 0.96276792 | N28: 0.95 | O28: =11/18282 -> 0.00060168472 | P28: 0.0025 | Q28: The Clock is Ticking | S28: AST
A29: Call for Abstracts Email #18 | B29: 2026 Attendee House Marketing List (excluding unsub & undeliverable & INTL "no") | C29: 45974 | D29: Thursday | E29: 0.58333333 | F29: 18971 | G29: 0.012 | H29: 0.15 | I29: 0.012 | J29: 0.03 | K29: 1 | L29: 0.06 | M29: =18264/18971 -> 0.96273259 | N29: 0.95 | O29: =4/18264 -> 0.00021901007 | P29: 0.0025 | Q29: Important Update: Abstracts Deadline Extended | S29: ASTS
A30: Call for Abstracts Email #19 (+ resend) | B30: 2026 Attendee House Marketing List (excluding unsub & undeliverable & INTL "no") | C30: 45980 | D30: Wednesday | E30: 0.58333333 | F30: 29132 | G30: 0.527 | H30: 0.15 | I30: 0.018 | J30: 0.03 | K30: =334/10042 -> 0.033260307 | L30: 0.06 | M30: =28341/29132 -> 0.97284773 | N30: 0.95 | O30: =11/28341 -> 0.00038813027 | P30: 0.0025 | Q30: Abstract Deadline is TOMORROW at 11:59 PM ET | S30: skip
A31: Awareness Email #4 Save the Date | B31: 2026 Attendee House Marketing List (excluding unsub & undeliverable & INTL "no") | C31: 45993 | D31: Tuesday | E31: 0.45833333 | F31: 18955 | G31: 0.416 | H31: 0.15 | I31: 0.015 | J31: 0.03 | K31: =267/7595 -> 0.035154707 | L31: 0.06 | M31: =18244/18955 -> 0.96249011 | N31: 0.95 | O31: =11/18244 -> 0.00060293795 | P31: 0.0025 | Q31: ATC 2026: Where The Transplant Ecosystem Unites | S31: AST
A32: Awareness Email #5A Save the Date | B32: 2026 Attendee House Marketing List (excluding unsubs & undeliverable & INTL)) | C32: 46008 | D32: Wednesday | E32: 0.58333333 | F32: 16335 | G32: 0.376 | H32: 0.15 | I32: 0.02 | J32: 0.03 | K32: =308/5885 -> 0.052336449 | L32: 0.06 | M32: =15642/16335 -> 0.95757576 | N32: 0.95 | O32: =7/15642 -> 0.00044751311 | P32: 0.0025 | Q32: Get Ready - Registration Opens Soon | S32: ASTS
A33: Awareness Email #5B Save the Date | B33: International Attendees | C33: 46008 | D33: Wednesday | E33: 0.58333333 | F33: 2367 | G33: 0.394 | H33: 0.15 | I33: 0.019 | J33: 0.03 | K33: =44/900 -> 0.048888889 | L33: 0.06 | M33: =2285/2367 -> 0.96535699 | N33: 0.95 | O33: =1/2285 -> 0.00043763676 | P33: 0.0025 | Q33: Get Ready - Registration Opens Soon | S33: ASTS
A34: Call for Abstracts Email #19.5 | B34: 2026 Attendee House Marketing List (excluding unsub & undeliverable & INTL "no") | C34: 46028 | D34: Monday | E34: 0.58333333 | F34: 18958 | G34: 0.429 | H34: 0.15 | I34: =194/18156 -> 0.010685173 | J34: 0.03 | K34: =194/7784 -> 0.024922919 | L34: 0.06 | M34: =18156/18958 -> 0.95769596 | N34: 0.95 | O34: =7/18156 -> 0.00038554748 | P34: 0.0025 | Q34: How to Prepare: Late-Breaking Abstracts Open Next Week | S34: skip
A35: Call for Late-Breaking Abstracts Email #20 | B35: 2026 Attendee House Marketing List (excluding unsub & undeliverable & INTL "no") | C35: 46034 | D35: Monday | E35: 0.45833333 | F35: 18968 | G35: 0.396 | H35: 0.15 | I35: =565/18123 -> 0.031175854 | J35: 0.03 | K35: =568/7184 -> 0.079064588 | L35: 0.06 | M35: =18123/18968 -> 0.95545129 | N35: 0.95 | O35: =4/18123 -> 0.00022071401 | P35: 0.0025 | Q35: Portal Open: Late-Breaking Abstracts | S35: AST
A36: Awareness Email #6 Save the Date | B36: 2026 Attendee House Marketing List (excluding unsub & undeliverable & INTL "no") | C36: 46037 | D36: Thursday | E36: 0.58333333 | F36: 19986 | G36: 0.417 | H36: 0.15 | I36: 0.019 | J36: 0.03 | K36: =340/7560 -> 0.044973545 | L36: 0.06 | M36: =18140/18986 -> 0.95544085 | N36: 0.95 | O36: =5/18140 -> 0.00027563396 | P36: 0.0025 | Q36: Your ATC 2026 Guide: 5 Days of Breakthroughs | S36: ASTS
A37: Call for Late Breaking Abstracts Email #21a | B37: International Attendees | C37: 46044 | D37: Thursday | E37: 0.45833333 | F37: 2362 | G37: 0.384 | H37: 0.15 | I37: 0.021 | J37: 0.03 | K37: =48/873 -> 0.054982818 | L37: 0.06 | M37: =2271/2362 -> 0.96147333 | N37: 0.95 | O37: 0 | P37: 0.0025 | Q37: Submit Your Late-Breaking Abstract for ATC 2026 | S37: skipped
A38: Call for Late Breaking Abstracts Email #21b | B38: 2026 Attendee House Marketing List (excluding unsubs & undeliverable & INTL)) | C38: 46044 | D38: Thursday | E38: 0.45833333 | F38: 16352 | G38: 0.385 | H38: 0.15 | I38: 0.032 | J38: 0.03 | K38: =494/6004 -> 0.082278481 | L38: 0.06 | M38: =15589/16352 -> 0.95333904 | N38: 0.95 | O38: 0.00032073898 | P38: 0.0025 | Q38: Submit Your Late-Breaking Abstract for ATC 2026 | S38: skipped
A39: Registration Email #1 | B39: 2026 Attendee House Marketing List (excluding unsub & undeliverable & INTL "no") | C39: 46048 | D39: Monday | E39: 0.47916667 | F39: 18763 | G39: 0.376 | H39: 0.15 | I39: 0.019 | J39: 0.03 | K39: =340/6879 -> 0.049425789 | L39: 0.06 | M39: =18310/18763 -> 0.97585674 | N39: 0.95 | O39: =7/18310 -> 0.00038230475 | P39: 0.0025 | Q39: {NOW OPEN} Register for ATC 2026 | S39: skipped
A40: Call for Late Breaking Abstracts Email #22 | B40: 2026 Attendee House Marketing List (excluding unsub & undeliverable & INTL "no") | C40: 46059 | D40: Friday | E40: 0.45833333 | F40: 18592 | G40: 0.611 | H40: 0.15 | I40: =106/18069 -> 0.005866401 | J40: 0.03 | K40: =106/11049 -> 0.0095936284 | L40: 0.06 | M40: =18069/18592 -> 0.97186962 | N40: 0.95 | O40: =1/18069 -> 5.5343406e-05 | P40: 0.0025 | Q40: 72 Hours Left: Late-Breaking Abstracts Due Feb. 9
...

Sheet Emails (Sponsored)
A1: ATC
A2: Email Name | B2: Audience (List) | C2: Deployment Date | D2: Deployment Day of Week | E2: Deployment Time of Day | F2: Total Emails Sent | G2: Open Rate | H2: Open Rate (Benchmark) | I2: Click-Through Rate (clicks / devilieries) | J2: CTR (Benchmark) | K2: Click-To-Open Rate | L2: CTO (Benchmark) | M2: Delivery Rate | N2: Delivery Rate (Benchmark) | O2: Unsubscribe % | P2: Unsubscribe % (Benchmark) | Q2: Subject Line | R2: Notes | S2: Footer
A3: Eurofins Sponsored EBlast 6/9/26 | B3: ATC Registrations | C3: 46182 | D3: Tuesday | E3: 0.40625 | F3: 3700 | G3: 0.54 | H3: 0.15 | I3: 0.04 | J3: 0.03 | K3: =145/1366 -> 0.10614934 | L3: 0.06 | M3: =3613/3700 -> 0.97648649 | N3: 0.95 | O3: =1/3613 -> 0.0002767783 | P3: 0.0025 | Q3: ATC Attendees: Exclusive Invites + Meet the Scientists
A4: Apellis Sponsored Eblast | B4: 6.11.26 Apellis Sponsor Email List | C4: 46184 | D4: Thursday | E4: 0.48958333 | F4: 1288 | G4: 0.536 | H4: 0.15 | I4: 0.029 | J4: 0.03 | K4: =37/473 -> 0.078224101 | L4: 0.06 | M4: =1261/1288 -> 0.97903727 | N4: 0.95 | O4: 0 | P4: 0.0025 | Q4: Attending ATC? Discover an option for your patients
H5: 0.15 | J5: 0.03 | L5: 0.06 | N5: 0.95 | P5: 0.0025
H6: 0.15 | J6: 0.03 | L6: 0.06 | N6: 0.95 | P6: 0.0025
H7: 0.15 | J7: 0.03 | L7: 0.06 | N7: 0.95 | P7: 0.0025
H8: 0.15 | J8: 0.03 | L8: 0.06 | N8: 0.95 | P8: 0.0025
H9: 0.15 | J9: 0.03 | L9: 0.06 | N9: 0.95 | P9: 0.0025
H10: 0.15 | J10: 0.03 | L10: 0.06 | N10: 0.95 | P10: 0.0025
H11: 0.15 | J11: 0.03 | L11: 0.06 | N11: 0.95 | P11: 0.0025
H12: 0.15 | J12: 0.03 | L12: 0.06 | N12: 0.95 | P12: 0.0025
H13: 0.15 | J13: 0.03 | L13: 0.06 | N13: 0.95 | P13: 0.0025
H14: 0.15 | J14: 0.03 | L14: 0.06 | N14: 0.95 | P14: 0.0025
H15: 0.15 | J15: 0.03 | L15: 0.06 | N15: 0.95 | P15: 0.0025
H16: 0.15 | J16: 0.03 | L16: 0.06 | N16: 0.95 | P16: 0.0025
... H87: 0.15 | J87: 0.03 | L87: 0.06 | N87: 0.95 | P87: 0.0025

Sheet Emails (2)
A1: ATC
A2: Email Name | B2: Open Rate | C2: Open Rate (Benchmark) | D2: Click-Through Rate | E2: CTR (Benchmark) | F2: Click-To-Open Rate | G2: CTO (Benchmark)
A3: Call for Abstracts Email #10 | B3: 0.443 | C3: 0.15 | D3: =222/17937 -> 0.012376652 | E3: 0.03 | F3: =222/7940 -> 0.027959698 | G3: 0.06
A4: Call for Abstracts Email #10.5 | B4: 0.095 | C4: 0.15 | D4: =499/5227 -> 0.09546585 | E4: 0.03 | F4: =499/499 -> 1 | G4: 0.06
A5: Call for Abstracts Email #11a | B5: 0.433 | C5: 0.15 | D5: 0.005 | E5: 0.03 | F5: =48/3998 -> 0.012006003 | G5: 0.06
A6: Call For Abstracts Email #11b | B6: 0.44 | C6: 0.15 | D6: =73/9201 -> 0.0079339202 | E6: 0.03 | F6: =73/4046 -> 0.018042511 | G6: 0.06
A7: Call for Abstracts Email #12a | B7: 0.467 | C7: 0.15 | D7: 0.027 | E7: 0.03 | F7: =71/1241 -> 0.057211926 | G7: 0.06
A8: Call for Abstracts Email #12b | B8: 0.42 | C8: 0.15 | D8: 0.0009 | E8: 0.03 | F8: =146/6578 -> 0.022195196 | G8: 0.06
A9: Call for Abstracts Email #13 | B9: 0.43 | C9: 0.15 | D9: 0.091 | E9: 0.03 | F9: =1668/7843 -> 0.21267372 | G9: 0.06
A10: Call for Abstracts Email #14 | B10: 0.524 | C10: 0.15 | D10: =189/18217 -> 0.010374925 | E10: 0.03 | F10: =189/9452 -> 0.019995768 | G10: 0.06
A11: Call for Abstracts Email #15 | B11: 0.365 | C11: 0.15 | D11: =169/18393 -> 0.0091882781 | E11: 0.03 | F11: =169/6719 -> 0.025152552 | G11: 0.06
A12: Call for Abstracts Email #16 | B12: 0.458 | C12: 0.15 | D12: 0.013 | E12: 0.03 | F12: =244/8397 -> 0.029057997 | G12: 0.06
A13: Call for Abstracts Email #17 | B13: 0.036 | C13: 0.15 | D13: 0.014 | E13: 0.03 | F13: =261/663 -> 0.39366516 | G13: 0.06
A14: Call for Abstracts Email #18 | B14: 0.012 | C14: 0.15 | D14: 0.012 | E14: 0.03 | F14: 1 | G14: 0.06
A15: Call for Abstracts Email #19 (+ resend) | B15: 0.527 | C15: 0.15 | D15: 0.018 | E15: 0.03 | F15: =334/10042 -> 0.033260307 | G15: 0.06
A16: Call for Abstracts Email #19.5 | B16: 0.429 | C16: 0.15 | D16: =194/18156 -> 0.010685173 | E16: 0.03 | F16: =194/7784 -> 0.024922919 | G16: 0.06
A17: Call for Late-Breaking Abstracts Email #20 | B17: 0.396 | C17: 0.15 | D17: =565/18123 -> 0.031175854 | E17: 0.03 | F17: =568/7184 -> 0.079064588 | G17: 0.06
A18: Call for Late Breaking Abstracts Email #21a | B18: 0.384 | C18: 0.15 | D18: 0.021 | E18: 0.03 | F18: =48/873 -> 0.054982818 | G18: 0.06
A19: Call for Late Breaking Abstracts Email #21b | B19: 0.385 | C19: 0.15 | D19: 0.032 | E19: 0.03 | F19: =494/6004 -> 0.082278481 | G19: 0.06
A20: Call for Late Breaking Abstracts Email #22 | B20: 0.611 | C20: 0.15 | D20: =106/18069 -> 0.005866401 | E20: 0.03 | F20: =106/11049 -> 0.0095936284 | G20: 0.06 | J20: =1/18069 -> 5.5343406e-05 | K20: 0.0025 | L20: 72 Hours Left: Late-Breaking Abstracts Due Feb. 9
C21: 0.15 | E21: 0.03 | G21: 0.06
C22: 0.15 | E22: 0.03 | G22: 0.06
C23: 0.15 | E23: 0.03 | G23: 0.06
C24: 0.15 | E24: 0.03 | G24: 0.06
C25: 0.15 | E25: 0.03 | G25: 0.06
C26: 0.15 | E26: 0.03 | G26: 0.06
C27: 0.15 | E27: 0.03 | G27: 0.06
C28: 0.15 | E28: 0.03 | G28: 0.06
C29: 0.15 | E29: 0.03 | G29: 0.06
C30: 0.15 | E30: 0.03 | G30: 0.06
C31: 0.15 | E31: 0.03 | G31: 0.06
C32: 0.15 | E32: 0.03 | G32: 0.06
... C36: 0.15 | E36: 0.03 | G36: 0.06
A37: ATC
A38: Email Name | B38: Open Rate | C38: Open Rate (Benchmark) | D38: Click-Through Rate (clicks / devilieries) | E38: CTR (Benchmark) | F38: Click-To-Open Rate | G38: CTO (Benchmark)
A39: Save the Date Email #1 | B39: 0.016 | C39: 0.15 | D39: =95/5939 -> 0.015995959 | E39: 0.03 | F39: 1 | G39: 0.06
A40: Save the Date Email #2 | B40: 0.01 | C40: 0.15 | D40: 0.01 | E40: 0.03 | F40: 1 | G40: 0.06
A41: Save the Date Email #3 | B41: 0.455 | C41: 0.15 | D41: =2113/18248 -> 0.11579351 | E41: 0.03 | F41: =2113/8304 -> 0.25445568 | G41: 0.06
A107: Awareness Email #4 Save the Date | B107: 0.416 | C107: 0.15 | D107: 0.015 | E107: 0.03 | F107: =267/7595 -> 0.035154707 | G107: 0.06
A108: Awareness Email #5A Save the Date | B108: 0.376 | C108: 0.15 | D108: 0.02 | E108: 0.03 | F108: =308/5885 -> 0.052336449 | G108: 0.06
...

Sheet Heatmap
A1: ATC
A2: Email Name | B2: Audience (List) | C2: Total Clicks | D2: Top Button Clicks | E2: % Total Clicked Top Button | F2: Top Logo Clicks | G2: % Total Clicked Top Logo | H2: Header Image Clicks | I2: % Total Clicked Header Image | J2: First Button Clicks | K2: % Total Clicked First Button
A3: Call for Proposals Email #1 (All Prospects) | C3: 1432 | D3: 358 | E3: =(D3/C3) -> 0.25 | F3: 347 | G3: =(F3/C3) -> 0.24231844 | H3: 346 | I3: =(H3/C3) -> 0.24162011 | J3: 381 | K3: =(J3/C3) -> 0.26606145
A4: Call for Proposals Email #2 (All Prospects) | C4: 10843 | D4: 3611 | E4: =(D4/C4) -> 0.33302592 | F4: 0 | G4: =(F4/C4) -> 0 | H4: 3613 | I4: =(H4/C4) -> 0.33321037 | J4: 3619 | K4: =(J4/C4) -> 0.33376372
A5: Call for Proposals Email #3 (All Prospects) | C5: 9810 | D5: =2433+8 -> 2441 | E5: =(D5/C5) -> 0.24882773 | F5: =1+2431 -> 2432 | G5: =(F5/C5) -> 0.2479103 | H5: =2428+3 -> 2431 | I5: =(H5/C5) -> 0.24780836 | J5: =21+2485 -> 2506 | K5: =(J5/C5) -> 0.25545362
A6: Call for Proposals Email #4a (Past Submitters) | C6: 109 | D6: 27 | E6: =(D6/C6) -> 0.24770642 | F6: 26 | G6: =(F6/C6) -> 0.23853211 | H6: 26 | I6: =(H6/C6) -> 0.23853211 | J6: 30 | K6: =(J6/C6) -> 0.27522936
A7: Call for Proposals Email #4b (All Prospects) | C7: 5882 | D7: 1466 | E7: =(D7/C7) -> 0.24923495 | F7: 1461 | G7: =(F7/C7) -> 0.2483849 | H7: 1462 | I7: =(H7/C7) -> 0.24855491 | J7: 1493 | K7: =(J7/C7) -> 0.25382523
A8: Call for Proposals Email #5 (All Prospects) | C8: 4142 | D8: 1051 | E8: =(D8/C8) -> 0.25374215 | F8: 1046 | G8: =(F8/C8) -> 0.25253501 | H8: 1017 | I8: =(H8/C8) -> 0.24553356 | J8: 1028 | K8: =(J8/C8) -> 0.24818928
A9: INTL Email #1 - Survey (International Attendees) | C9: 224 | D9: =54+3 -> 57 | E9: =(D9/C9) -> 0.25446429 | F9: =54+3 -> 57 | G9: =(F9/C9) -> 0.25446429 | H9: =4+55 -> 59 | I9: =(H9/C9) -> 0.26339286 | J9: =48+3 -> 51 | K9: =(J9/C9) -> 0.22767857
A10: Call for Proposals Email #6 (All Prospects) | C10: 937 | D10: =222+13 -> 235 | E10: =(D10/C10) -> 0.25080043 | F10: =8+217 -> 225 | G10: =(F10/C10) -> 0.24012807 | H10: =213+11 -> 224 | I10: =(H10/C10) -> 0.23906083 | J10: =10+243 -> 253 | K10: =(J10/C10) -> 0.27001067
A11: Call for Proposals Email #7 (All Prospects) | C11: 1043 | D11: 256 | E11: =(D11/C11) -> 0.24544583 | F11: 235 | G11: =(F11/C11) -> 0.2253116 | H11: 248 | I11: =(H11/C11) -> 0.23777565 | J11: 304 | K11: =(J11/C11) -> 0.29146692
A12: Call for Proposals Email #8 (All Prospects) | C12: 136 | D12: 23 | E12: =(D12/C12) -> 0.16911765 | F12: 14 | G12: =(F12/C12) -> 0.10294118 | H12: 22 | I12: =(H12/C12) -> 0.16176471 | J12: 77 | K12: =(J12/C12) -> 0.56617647
A13: Call for Proposals & State-of-the-Art Speakers Email #9.5 Deadline Extended (All Prospects) | C13: 684 | D13: 185 | E13: =(D13/C13) -> 0.27046784 | F13: 170 | G13: =(F13/C13) -> 0.24853801 | H13: 150 | I13: =(H13/C13) -> 0.21929825 | J13: 179 | K13: =(J13/C13) -> 0.26169591
A14: Call for Abstracts - Email #10 (All Prospects) | C14: 261 | D14: 58 | E14: =(D14/C14) -> 0.22222222 | F14: 69 | G14: =(F14/C14) -> 0.26436782 | H14: 57 | I14: =(H14/C14) -> 0.2183908 | J14: 77 | K14: =(J14/C14) -> 0.29501916
A15: Email #9 - Call for Proposals - 24 Hours Left 8/21 (All Prospects) | C15: 1092 | D15: 25 | E15: =(D15/C15) -> 0.022893773 | F15: 25 | G15: =(F15/C15) -> 0.022893773 | H15: 31 | I15: =(H15/C15) -> 0.028388278 | J15: 1011 | K15: =(J15/C15) -> 0.92582418
A16: Email #10.5 - Call for Abstracts - Past Attendees & Past Abstract Submitters (Past Abstract Submitters & Attendees) | C16: 887 | D16: 213 | E16: =(D16/C16) -> 0.24013529 | F16: 305 | G16: =(F16/C16) -> 0.34385569 | H16: 194 | I16: =(H16/C16) -> 0.21871477 | J16: 175 | K16: =(J16/C16) -> 0.19729425
A17: Save the Date Email #1 | C17: 80 | D17: 17 | E17: =(D17/C17) -> 0.2125 | F17: 18 | G17: =(F17/C17) -> 0.225 | H17: 38 | I17: =(H17/C17) -> 0.475 | J17: 7 | K17: =(J17/C17) -> 0.0875
A18: Save the Date Email #2 | C18: 151 | D18: 26 | E18: =(D18/C18) -> 0.17218543 | F18: 32 | G18: =(F18/C18) -> 0.21192053 | H18: 46 | I18: =(H18/C18) -> 0.30463576 | J18: 47 | K18: =(J18/C18) -> 0.31125828
A19: Email #11a Call for Abstracts Button Test | C19: 43 | D19: 0 | E19: =(D19/C19) -> 0 | F19: 43 | G19: =(F19/C19) -> 1 | H19: 0 | I19: =(H19/C19) -> 0 | J19: 0 | K19: =(J19/C19) -> 0
A20: Email #11b Call For Abstracts Button Test | C20: 57 | D20: 16 | E20: =(D20/C20) -> 0.28070175 | F20: 12 | G20: =(F20/C20) -> 0.21052632 | H20: 11 | I20: =(H20/C20) -> 0.19298246 | J20: 18 | K20: =(J20/C20) -> 0.31578947
A21: Email #12a Visa Focus | C21: 63 | D21: 16 | E21: =(D21/C21) -> 0.25396825 | F21: 14 | G21: =(F21/C21) -> 0.22222222 | H21: 15 | I21: =(H21/C21) -> 0.23809524 | J21: 18 | K21: =(J21/C21) -> 0.28571429
A22: Email #12b | C22: =55+50+37+53 -> 195 | D22: 55 | E22: =(D22/C22) -> 0.28205128 | F22: 50 | G22: =(F22/C22) -> 0.25641026 | H22: 37 | I22: =(H22/C22) -> 0.18974359 | J22: 53 | K22: =(J22/C22) -> 0.27179487
E23: =(D23/C23) -> #DIV/0! | G23: =(F23/C23) -> #DIV/0! | I23: =(H23/C23) -> #DIV/0! | K23: =(J23/C23) -> #DIV/0!
E24: =(D24/C24) -> #DIV/0!
A27: Average: | C27: =AVERAGE(C3:C20) -> 2100.7222 | D27: =AVERAGE(D3:D20) -> 559.16667 | E27: =AVERAGE(E3:E20) -> 0.21797065 | F27: =AVERAGE(F3:F20) -> 362.05556 | G27: =AVERAGE(G3:G20) -> 0.25442378 | H27: =AVERAGE(H3:H20) -> 554.16667 | I27: =AVERAGE(I3:I20) -> 0.22859243 | J27: =AVERAGE(J3:J20) -> 625.33333 | K27: =AVERAGE(K3:K20) -> 0.29901314

Sheet Organic Social Media (Weekly)
A1: Social Media
B2: LinkedIn (LI) | G2: Facebook (FB) | L2: Instagram (IG) | Q2: Twitter (X) | V2: Totals
A3: Notes > | B3: Total followers to start the week. | C3: Percentage change in followers over time. | D3: Every time someone sees our post, even if they just scroll past | E3: When someone actually interacts with our post, like commenting, liking, or sharing, that's an engagement. | F3: How many times we posted this week about the event | G3: Total followers to start the week. | H3: Percentage change in followers over time. | I3: Every time someone sees our post, even if they just scroll past | J3: When someone actually interacts with our post, like commenting, liking, or sharing, that's an engagement. | K3: How many times we posted this week about the event | L3: Total followers to start the week. | M3: Percentage change in followers over time. | N3: Every time someone sees our post, even if they just scroll past (view) | O3: When someone actually interacts with our post, like commenting, liking, or sharing, that's an engagement. | P3: How many times we posted this week about the event | Q3: Total followers to start the week. | R3: Percentage change in followers over time. | S3: Every time someone sees our post, even if they just scroll past | T3: When someone actually interacts with our post, like commenting, liking, or sharing, that's an engagement. | U3: How many times we posted this week about the event | V3: Followers | AB3: Follower Growth Rate | AF3: Impressions | AJ3: Engagements | AO3: Posts Per Week
A4: Week Starting | B4: LI Followers | C4: LI Follower Growth Rate | D4: LI Impressions | E4: LI Engagements | F4: LI Posts Per Week | G4: FB Followers | H4: FB Follower Growth Rate | I4: FB Impressions | J4: FB Engagements | K4: FB Posts Per Week | L4: IG Followers | M4: IG Follower Growth Rate | N4: IG Impressions | O4: IG Engagements | P4: IG Posts Per Week | Q4: X Followers | R4: X Follower Growth Rate | S4: X Impressions | T4: X Engagements | U4: X Posts Per Week | V4: LI Followers | W4: FB Followers | X4: IG Followers | Y4: X Followers | Z4: Total Followers | AB4: LI Growth Rate | AC4: FB Growth Rate | AD4: IG Growth Rate | AE4: X Growth Rate | AF4: LI Impressions | AG4: FB Impressions | AH4: IG Impressions | AI4: X Impressions | AJ4: LI Engagements | AK4: FB Engagements | AL4: IG Engagements | AM4: X Engagements | AN4: Total Engagements | AO4: LI Posts Per Week | AP4: FB Posts Per Week | AQ4: IG Posts Per Week | AR4: X Posts Per Week | AS4: Total posts per week
A5: 45831 | B5: 1490 | C5: =(B6/B5)-1 -> -0.00067114094 | D5: 807 | E5: 26 | F5: 2 | G5: 2311 | H5: =(G6/G5)-1 -> -0.00086542622 | I5: 329 | J5: 10 | K5: 2 | L5: 921 | M5: =(L6/L5)-1 -> 0.0021715527 | N5: 384 | O5: 15 | P5: 2 | Q5: 5627 | R5: =(Q6/Q5)-1 -> 0 | S5: 1141 | T5: 24 | U5: 3 | V5: =B5 -> 1490 | W5: =G5 -> 2311 | X5: =L5 -> 921 | Y5: =Q5 -> 5627 | AA5: =(Z5-Z4)/Z4 -> #VALUE! | AB5: =C5 -> -0.00067114094 | AC5: =H5 -> -0.00086542622 | AD5: =M5 -> 0.0021715527 | AE5: =R5 -> 0 | AF5: =D5 -> 807 | AG5: =I5 -> 329 | AH5: =N5 -> 384 | AI5: =S5 -> 1141 | AJ5: =E5 -> 26 | AK5: =J5 -> 10 | AL5: =O5 -> 15 | AM5: =T5 -> 24 | AN5: =SUM(AJ5:AM5) -> 75 | AO5: =F5 -> 2 | AP5: =K5 -> 2 | AQ5: =P5 -> 2 | AR5: =U5 -> 3 | AS5: =SUM(AO5:AR5) -> 9
A6: 45838 | B6: 1489 | C6: =(B6-B5)/B5 -> -0.00067114094 | D6: 179 | E6: 3 | F6: 0 | G6: 2309 | H6: =(G7/G6)-1 -> 0 | I6: 18 | J6: 0 | K6: 0 | L6: 923 | M6: =(L7/L6)-1 -> 0.0054171181 | N6: 87 | O6: 2 | P6: 0 | Q6: 5627 | R6: =(Q7/Q6)-1 -> -0.00035542918 | S6: 107 | T6: 8 | U6: 0 | V6: =B6 -> 1489 | W6: =G6 -> 2309 | X6: =L6 -> 923 | Y6: =Q6 -> 5627 | AB6: =C6 -> -0.00067114094 | AC6: =H6 -> 0 | AD6: =M6 -> 0.0054171181 | AE6: =R6 -> -0.00035542918 | AF6: =D6 -> 179 | AG6: =I6 -> 18 | AH6: =N6 -> 87 | AI6: =S6 -> 107 | AJ6: =E6 -> 3 | AK6: =J6 -> 0 | AL6: =O6 -> 2 | AM6: =T6 -> 8 | AN6: =SUM(AJ6:AM6) -> 13 | AO6: =F6 -> 0 | AP6: =K6 -> 0 | AQ6: =P6 -> 0 | AR6: =U6 -> 0 | AS6: =SUM(AO6:AR6) -> 0
A7: 45845 | B7: 1488 | C7: =(B7-B6)/B6 -> -0.00067159167 | D7: 293 | E7: 4 | F7: 1 | G7: 2309 | H7: =(G8/G7)-1 -> -0.00043308792 | I7: 94 | J7: 0 | K7: 1 | L7: 928 | M7: =(L8/L7)-1 -> -0.0021551724 | N7: 174 | O7: 7 | P7: 1 | Q7: 5625 | R7: =(Q8/Q7)-1 -> 0.0012444444 | S7: 644 | T7: 17 | U7: 1 | V7: =B7 -> 1488 | W7: =G7 -> 2309 | X7: =L7 -> 928 | Y7: =Q7 -> 5625 | AB7: =C7 -> -0.00067159167 | AC7: =H7 -> -0.00043308792 | AD7: =M7 -> -0.0021551724 | AE7: =R7 -> 0.0012444444 | AF7: =D7 -> 293 | AG7: =I7 -> 94 | AH7: =N7 -> 174 | AI7: =S7 -> 644 | AJ7: =E7 -> 4 | AK7: =J7 -> 0 | AL7: =O7 -> 7 | AM7: =T7 -> 17 | AN7: =SUM(AJ7:AM7) -> 28 | AO7: =F7 -> 1 | AP7: =K7 -> 1 | AQ7: =P7 -> 1 | AR7: =U7 -> 1 | AS7: =SUM(AO7:AR7) -> 4
A8: 45852 | B8: 1490 | C8: =(B8-B7)/B7 -> 0.001344086 | D8: 715 | E8: 12 | F8: 1 | G8: 2308 | H8: =(G9/G8)-1 -> 0 | I8: 87 | J8: 2 | K8: 1 | L8: 926 | M8: =(L9/L8)-1 -> -0.0010799136 | N8: 330 | O8: 6 | P8: 1 | Q8: 5632 | R8: =(Q9/Q8)-1 -> 0.0010653409 | S8: 440 | T8: 7 | U8: 1 | V8: =B8 -> 1490 | W8: =G8 -> 2308 | X8: =L8 -> 926 | Y8: =Q8 -> 5632 | AB8: =C8 -> 0.001344086 | AC8: =H8 -> 0 | AD8: =M8 -> -0.0010799136 | AE8: =R8 -> 0.0010653409 | AF8: =D8 -> 715 | AG8: =I8 -> 87 | AH8: =N8 -> 330 | AI8: =S8 -> 440 | AJ8: =E8 -> 12 | AK8: =J8 -> 2 | AL8: =O8 -> 6 | AM8: =T8 -> 7 | AN8: =SUM(AJ8:AM8) -> 27 | AO8: =F8 -> 1 | AP8: =K8 -> 1 | AQ8: =P8 -> 1 | AR8: =U8 -> 1 | AS8: =SUM(AO8:AR8) -> 4
A9: 45859 | B9: 1491 | C9: =(B9-B8)/B8 -> 0.00067114094 | D9: 526 | E9: 9 | F9: 2 | G9: 2308 | H9: =(G10/G9)-1 -> 0 | I9: 92 | J9: 1 | K9: 2 | L9: 925 | M9: =(L10/L9)-1 -> 0 | N9: 215 | O9: 6 | P9: 2 | Q9: 5638 | R9: =(Q10/Q9)-1 -> 0.00035473572 | S9: 428 | T9: 13 | U9: 2 | V9: =B9 -> 1491 | W9: =G9 -> 2308 | X9: =L9 -> 925 | Y9: =Q9 -> 5638 | AB9: =C9 -> 0.00067114094 | AC9: =H9 -> 0 | AD9: =M9 -> 0 | AE9: =R9 -> 0.00035473572 | AF9: =D9 -> 526 | AG9: =I9 -> 92 | AH9: =N9 -> 215 | AI9: =S9 -> 428 | AJ9: =E9 -> 9 | AK9: =J9 -> 1 | AL9: =O9 -> 6 | AM9: =T9 -> 13 | AN9: =SUM(AJ9:AM9) -> 29 | AO9: =F9 -> 2 | AP9: =K9 -> 2 | AQ9: =P9 -> 2 | AR9: =U9 -> 2 | AS9: =SUM(AO9:AR9) -> 8
A10: 45866 | B10: 1492 | C10: =(B10-B9)/B9 -> 0.00067069081 | D10: 519 | E10: 12 | F10: 1 | G10: 2308 | H10: =(G10-G9)/G9 -> 0 | I10: 81 | J10: 2 | K10: 1 | L10: 925 | M10: =(L10-L9)/L9 -> 0 | N10: 730 | O10: 14 | P10: 2 | Q10: 5640 | R10: =(Q11/Q10)-1 -> 0.00070921986 | S10: 435 | T10: 15 | U10: 1 | V10: =B10 -> 1492 | W10: =G10 -> 2308 | X10: =L10 -> 925 | Y10: =Q10 -> 5640 | AB10: =C10 -> 0.00067069081 | AC10: =H10 -> 0 | AD10: =M10 -> 0 | AE10: =R10 -> 0.00070921986 | AF10: =D10 -> 519 | AG10: =I10 -> 81 | AH10: =N10 -> 730 | AI10: =S10 -> 435 | AJ10: =E10 -> 12 | AK10: =J10 -> 2 | AL10: =O10 -> 14 | AM10: =T10 -> 15 | AN10: =SUM(AJ10:AM10) -> 43 | AO10: =F10 -> 1 | AP10: =K10 -> 1 | AQ10: =P10 -> 2 | AR10: =U10 -> 1 | AS10: =SUM(AO10:AR10) -> 5
A11: 45873 | B11: 1498 | C11: =(B11-B10)/B10 -> 0.0040214477 | D11: 812 | E11: 71 | F11: 3 | G11: 2307 | H11: =(G11-G10)/G10 -> -0.00043327556 | I11: 277 | J11: 2 | K11: 3 | L11: 935 | M11: =(L11-L10)/L10 -> 0.010810811 | N11: 1405 | O11: 10 | P11: 1 | Q11: 5644 | R11: =(Q11-Q10)/Q10 -> 0.00070921986 | S11: 1058 | T11: 109 | U11: 2 | V11: =B11 -> 1498 | W11: =G11 -> 2307 | X11: =L11 -> 935 | Y11: =Q11 -> 5644 | AB11: =C11 -> 0.0040214477 | AC11: =H11 -> -0.00043327556 | AD11: =M11 -> 0.010810811 | AE11: =R11 -> 0.00070921986 | AF11: =D11 -> 812 | AG11: =I11 -> 277 | AH11: =N11 -> 1405 | AI11: =S11 -> 1058 | AJ11: =E11 -> 71 | AK11: =J11 -> 2 | AL11: =O11 -> 10 | AM11: =T11 -> 109 | AN11: =SUM(AJ11:AM11) -> 192 | AO11: =F11 -> 3 | AP11: =K11 -> 3 | AQ11: =P11 -> 1 | AR11: =U11 -> 2 | AS11: =SUM(AO11:AR11) -> 9
A12: 45880 | B12: 1502 | C12: =(B12-B11)/B11 -> 0.002670227 | D12: 347 | E12: 12 | F12: 1 | G12: 2309 | H12: =(G12-G11)/G11 -> 0.00086692674 | I12: 178 | J12: 8 | K12: 1 | L12: 943 | M12: =(L12-L11)/L11 -> 0.0085561497 | N12: 987 | O12: 23 | P12: 4 | Q12: 5647 | R12: =(Q12-Q11)/Q11 -> 0.00053153792 | S12: 820 | T12: 18 | U12: 1 | V12: =B12 -> 1502 | W12: =G12 -> 2309 | X12: =L12 -> 943 | Y12: =Q12 -> 5647 | AB12: =C12 -> 0.002670227 | AC12: =H12 -> 0.00086692674 | AD12: =M12 -> 0.0085561497 | AE12: =R12 -> 0.00053153792 | AF12: =D12 -> 347 | AG12: =I12 -> 178 | AH12: =N12 -> 987 | AI12: =S12 -> 820 | AJ12: =E12 -> 12 | AK12: =J12 -> 8 | AL12: =O12 -> 23 | AM12: =T12 -> 18 | AN12: =SUM(AJ12:AM12) -> 61 | AO12: =F12 -> 1 | AP12: =K12 -> 1 | AQ12: =P12 -> 4 | AR12: =U12 -> 1 | AS12: =SUM(AO12:AR12) -> 7
A13: 45887 | B13: 1501 | C13: =(B13-B12)/B12 -> -0.00066577896 | D13: 368 | E13: 22 | F13: 2 | G13: 2309 | H13: =(G13-G12)/G12 -> 0 | I13: 201 | J13: 3 | K13: 2 | L13: 941 | M13: =(L13-L12)/L12 -> -0.0021208908 | N13: 576 | O13: 7 | P13: 2 | Q13: 5655 | R13: =(Q13-Q12)/Q12 -> 0.0014166814 | S13: 806 | T13: 37 | U13: 2 | V13: =B13 -> 1501 | W13: =G13 -> 2309 | X13: =L13 -> 941 | Y13: =Q13 -> 5655 | AB13: =C13 -> -0.00066577896 | AC13: =H13 -> 0 | AD13: =M13 -> -0.0021208908 | AE13: =R13 -> 0.0014166814 | AF13: =D13 -> 368 | AG13: =I13 -> 201 | AH13: =N13 -> 576 | AI13: =S13 -> 806 | AJ13: =E13 -> 22 | AK13: =J13 -> 3 | AL13: =O13 -> 7 | AM13: =T13 -> 37 | AN13: =SUM(AJ13:AM13) -> 69 | AO13: =F13 -> 2 | AP13: =K13 -> 2 | AQ13: =P13 -> 2 | AR13: =U13 -> 2 | AS13: =SUM(AO13:AR13) -> 8
A14: 45894 | B14: 1506 | C14: =(B14-B13)/B13 -> 0.0033311126 | D14: 209 | E14: 7 | F14: 1 | G14: 2307 | H14: =(G14-G13)/G13 -> -0.00086617583 | I14: 79 | J14: 4 | K14: 1 | L14: 941 | M14: =(L14-L13)/L13 -> 0 | N14: 170 | O14: 2 | P14: 1 | Q14: 5665 | R14: =(Q14-Q13)/Q13 -> 0.0017683466 | S14: 261 | T14: 2 | U14: 1 | V14: =B14 -> 1506 | W14: =G14 -> 2307 | X14: =L14 -> 941 | Y14: =Q14 -> 5665 | AB14: =C14 -> 0.0033311126 | AC14: =H14 -> -0.00086617583 | AD14: =M14 -> 0 | AE14: =R14 -> 0.0017683466 | AF14: =D14 -> 209 | AG14: =I14 -> 79 | AH14: =N14 -> 170 | AI14: =S14 -> 261 | AJ14: =E14 -> 7 | AK14: =J14 -> 4 | AL14: =O14 -> 2 | AM14: =T14 -> 2 | AN14: =SUM(AJ14:AM14) -> 15 | AO14: =F14 -> 1 | AP14: =K14 -> 1 | AQ14: =P14 -> 1 | AR14: =U14 -> 1 | AS14: =SUM(AO14:AR14) -> 4
A15: 45901 | B15: 1508 | C15: =(B15-B14)/B14 -> 0.0013280212 | D15: 134 | E15: 3 | F15: 0 | G15: 2309 | H15: =(G15-G14)/G14 -> 0.00086692674 | I15: 31 | J15: 0 | K15: 0 | L15: 940 | M15: =(L15-L14)/L14 -> -0.0010626993 | N15: 142 | O15: 0 | P15: 0 | Q15: 5666 | R15: =(Q15-Q14)/Q14 -> 0.00017652251 | S15: 297 | T15: 7 | U15: 0 | V15: =B15 -> 1508 | W15: =G15 -> 2309 | X15: =L15 -> 940 | Y15: =Q15 -> 5666 | AB15: =C15 -> 0.0013280212 | AC15: =H15 -> 0.00086692674 | AD15: =M15 -> -0.0010626993 | AE15: =R15 -> 0.00017652251 | AF15: =D15 -> 134 | AG15: =I15 -> 31 | AH15: =N15 -> 142 | AI15: =S15 -> 297 | AJ15: =E15 -> 3 | AK15: =J15 -> 0 | AL15: =O15 -> 0 | AM15: =T15 -> 7 | AN15: =SUM(AJ15:AM15) -> 10 | AO15: =F15 -> 0 | AP15: =K15 -> 0 | AQ15: =P15 -> 0 | AR15: =U15 -> 0 | AS15: =SUM(AO15:AR15) -> 0
A16: 45908 | B16: 1509 | C16: =(B16-B15)/B15 -> 0.00066312997 | D16: 129 | E16: 3 | F16: 1 | G16: 2311 | H16: =(G16-G15)/G15 -> 0.00086617583 | I16: 92 | J16: 3 | K16: 1 | L16: 940 | M16: =(L16-L15)/L15 -> 0 | N16: 411 | O16: 2 | P16: 1 | Q16: 5674 | R16: =(Q16-Q15)/Q15 -> 0.0014119308 | S16: 1271 | T16: 28 | U16: 1 | V16: =B16 -> 1509 | W16: =G16 -> 2311 | X16: =L16 -> 940 | Y16: =Q16 -> 5674 | Z16: =SUM(V16:Y16) -> 10434 | AA16: =(Z16-Z15)/Z15 -> #DIV/0! | AB16: =C16 -> 0.00066312997 | AC16: =H16 -> 0.00086617583 | AD16: =M16 -> 0 | AE16: =R16 -> 0.0014119308 | AF16: =D16 -> 129 | AG16: =I16 -> 92 | AH16: =N16 -> 411 | AI16: =S16 -> 1271 | AJ16: =E16 -> 3 | AK16: =J16 -> 3 | AL16: =O16 -> 2 | AM16: =T16 -> 28 | AN16: =SUM(AJ16:AM16) -> 36 | AO16: =F16 -> 1 | AP16: =K16 -> 1 | AQ16: =P16 -> 1 | AR16: =U16 -> 1 | AS16: =SUM(AO16:AR16) -> 4
A17: 45915 | B17: 1510 | C17: =(B17-B16)/B16 -> 0.00066269052 | D17: 277 | E17: 8 | F17: 1 | G17: 2310 | H17: =(G17-G16)/G16 -> -0.00043271311 | I17: 65 | J17: 2 | K17: 1 | L17: 940 | M17: =(L17-L16)/L16 -> 0 | N17: 513 | O17: 5 | P17: 1 | Q17: 5677 | R17: =(Q17-Q16)/Q16 -> 0.00052872753 | S17: 326 | T17: 6 | U17: 1 | V17: =B17 -> 1510 | W17: =G17 -> 2310 | X17: =L17 -> 940 | Y17: =Q17 -> 5677 | Z17: =SUM(V17:Y17) -> 10437 | AA17: =(Z17-Z16)/Z16 -> 0.00028752156 | AB17: =C17 -> 0.00066269052 | AC17: =H17 -> -0.00043271311 | AD17: =M17 -> 0 | AE17: =R17 -> 0.00052872753 | AF17: =D17 -> 277 | AG17: =I17 -> 65 | AH17: =N17 -> 513 | AI17: =S17 -> 326 | AJ17: =E17 -> 8 | AK17: =J17 -> 2 | AL17: =O17 -> 5 | AM17: =T17 -> 6 | AN17: =SUM(AJ17:AM17) -> 21 | AO17: =F17 -> 1 | AP17: =K17 -> 1 | AQ17: =P17 -> 1 | AR17: =U17 -> 1 | AS17: =SUM(AO17:AR17) -> 4
A18: 45922 | B18: 1512 | C18: =(B18-B17)/B17 -> 0.0013245033 | D18: 228 | E18: 5 | F18: 1 | G18: 2313 | H18: =(G18-G17)/G17 -> 0.0012987013 | I18: 44 | J18: 2 | K18: 1 | L18: 941 | M18: =(L18-L17)/L17 -> 0.0010638298 | N18: 242 | O18: 4 | P18: 1 | Q18: 5672 | R18: =(Q18-Q17)/Q17 -> -0.00088074687 | S18: 563 | T18: 17 | U18: 1 | V18: =B18 -> 1512 | W18: =G18 -> 2313 | X18: =L18 -> 941 | Y18: =Q18 -> 5672 | Z18: e | AA18: =(Z18-Z17)/Z17 -> #VALUE! | AB18: =C18 -> 0.0013245033 | AC18: =H18 -> 0.0012987013 | AD18: =M18 -> 0.0010638298 | AE18: =R18 -> -0.00088074687 | AF18: =D18 -> 228 | AG18: =I18 -> 44 | AH18: =N18 -> 242 | AI18: =S18 -> 563 | AJ18: =E18 -> 5 | AK18: =J18 -> 2 | AL18: =O18 -> 4 | AM18: =T18 -> 17 | AN18: =SUM(AJ18:AM18) -> 28 | AO18: =F18 -> 1 | AP18: =K18 -> 1 | AQ18: =P18 -> 1 | AR18: =U18 -> 1 | AS18: =SUM(AO18:AR18) -> 4
A19: 45929 | B19: 1517 | C19: =(B19-B18)/B18 -> 0.0033068783 | D19: 103 | E19: 0 | F19: 0 | G19: 2313 | H19: =(G19-G18)/G18 -> 0 | I19: 2 | J19: 1 | K19: 0 | L19: 942 | M19: =(L19-L18)/L18 -> 0.0010626993 | N19: 853 | O19: 0 | P19: 0 | Q19: 5682 | R19: =(Q19-Q18)/Q18 -> 0.0017630465 | S19: 126 | T19: 5 | U19: 0 | V19: =B19 -> 1517 | W19: =G19 -> 2313 | X19: =L19 -> 942 | Y19: =Q19 -> 5682 | Z19: =SUM(V19:Y19) -> 10454 | AA19: =(Z19-Z18)/Z18 -> #VALUE! | AB19: =C19 -> 0.0033068783 | AC19: =H19 -> 0 | AD19: =M19 -> 0.0010626993 | AE19: =R19 -> 0.0017630465 | AF19: =D19 -> 103 | AG19: =I19 -> 2 | AH19: =N19 -> 853 | AI19: =S19 -> 126 | AJ19: =E19 -> 0 | AK19: =J19 -> 1 | AL19: =O19 -> 0 | AM19: =T19 -> 5 | AN19: =SUM(AJ19:AM19) -> 6 | AO19: =F19 -> 0 | AP19: =K19 -> 0 | AQ19: =P19 -> 0 | AR19: =U19 -> 0 | AS19: =SUM(AO19:AR19) -> 0
A20: 45936 | B20: 1518 | C20: =(B20-B19)/B19 -> 0.00065919578 | D20: 223 | E20: 8 | F20: 1 | G20: 2313 | H20: =(G20-G19)/G19 -> 0 | I20: 38 | J20: 2 | K20: 1 | L20: 943 | M20: =(L20-L19)/L19 -> 0.0010615711 | N20: 542 | O20: 7 | P20: 1 | Q20: 5680 | R20: =(Q20-Q19)/Q19 -> -0.00035198874 | S20: 354 | T20: 18 | U20: 1 | V20: =B20 -> 1518 | W20: =G20 -> 2313 | X20: =L20 -> 943 | Y20: =Q20 -> 5680 | Z20: =SUM(V20:Y20) -> 10454 | AA20: =(Z20-Z19)/Z19 -> 0 | AB20: =C20 -> 0.00065919578 | AC20: =H20 -> 0 | AD20: =M20 -> 0.0010615711 | AE20: =R20 -> -0.00035198874 | AF20: =D20 -> 223 | AG20: =I20 -> 38 | AH20: =N20 -> 542 | AI20: =S20 -> 354 | AJ20: =E20 -> 8 | AK20: =J20 -> 2 | AL20: =O20 -> 7 | AM20: =T20 -> 18 | AN20: =SUM(AJ20:AM20) -> 35 | AO20: =F20 -> 1 | AP20: =K20 -> 1 | AQ20: =P20 -> 1 | AR20: =U20 -> 1 | AS20: =SUM(AO20:AR20) -> 4
A21: 45943 | B21: 1519 | C21: =(B21-B20)/B20 -> 0.00065876153 | D21: 402 | E21: 7 | F21: 1 | G21: 2311 | H21: =(G21-G20)/G20 -> -0.00086467791 | I21: 82 | J21: 3 | K21: 1 | L21: 951 | M21: =(L21-L20)/L20 -> 0.0084835631 | N21: 1273 | O21: 15 | P21: 1 | Q21: 5678 | R21: =(Q21-Q20)/Q20 -> -0.00035211268 | S21: 787 | T21: 21 | U21: 1 | V21: =B21 -> 1519 | W21: =G21 -> 2311 | X21: =L21 -> 951 | Y21: =Q21 -> 5678 | Z21: =SUM(V21:Y21) -> 10459 | AA21: =(Z21-Z20)/Z20 -> 0.00047828582 | AB21: =C21 -> 0.00065876153 | AC21: =H21 -> -0.00086467791 | AD21: =M21 -> 0.0084835631 | AE21: =R21 -> -0.00035211268 | AF21: =D21 -> 402 | AG21: =I21 -> 82 | AH21: =N21 -> 1273 | AI21: =S21 -> 787 | AJ21: =E21 -> 7 | AK21: =J21 -> 3 | AL21: =O21 -> 15 | AM21: =T21 -> 21 | AN21: =SUM(AJ21:AM21) -> 46 | AO21: =F21 -> 1 | AP21: =K21 -> 1 | AQ21: =P21 -> 1 | AR21: =U21 -> 1 | AS21: =SUM(AO21:AR21) -> 4
A22: 45950 | B22: 1520 | C22: =(B22-B21)/B21 -> 0.00065832785 | D22: 209 | E22: 10 | F22: 0 | G22: 2310 | H22: =(G22-G21)/G21 -> -0.00043271311 | I22: 19 | J22: 1 | K22: 0 | L22: 956 | M22: =(L22-L21)/L21 -> 0.0052576236 | N22: 662 | O22: 1 | P22: 0 | Q22: 5679 | R22: =(Q22-Q21)/Q21 -> 0.00017611835 | S22: 97 | T22: 4 | U22: 0 | V22: =B22 -> 1520 | W22: =G22 -> 2310 | X22: =L22 -> 956 | Y22: =Q22 -> 5679 | Z22: =SUM(V22:Y22) -> 10465 | AA22: =(Z22-Z21)/Z21 -> 0.00057366861 | AB22: =C22 -> 0.00065832785 | AC22: =H22 -> -0.00043271311 | AD22: =M22 -> 0.0052576236 | AE22: =R22 -> 0.00017611835 | AF22: =D22 -> 209 | AG22: =I22 -> 19 | AH22: =N22 -> 662 | AI22: =S22 -> 97 | AJ22: =E22 -> 10 | AK22: =J22 -> 1 | AL22: =O22 -> 1 | AM22: =T22 -> 4 | AN22: =SUM(AJ22:AM22) -> 16 | AO22: =F22 -> 0 | AP22: =K22 -> 0 | AQ22: =P22 -> 0 | AR22: =U22 -> 0 | AS22: =SUM(AO22:AR22) -> 0
A23: 45957 | B23: 1522 | C23: =(B23-B22)/B22 -> 0.0013157895 | D23: 343 | E23: 12 | F23: 2 | G23: 2312 | H23: =(G23-G22)/G22 -> 0.00086580087 | I23: 80 | J23: 7 | K23: 2 | L23: 958 | M23: =(L23-L22)/L22 -> 0.0020920502 | N23: 896 | O23: 6 | P23: 2 | Q23: 5678 | R23: =(Q23-Q22)/Q22 -> -0.00017608734 | S23: 447 | T23: 9 | U23: 2 | V23: =B23 -> 1522 | W23: =G23 -> 2312 | X23: =L23 -> 958 | Y23: =Q23 -> 5678 | Z23: =SUM(V23:Y23) -> 10470 | AA23: =(Z23-Z22)/Z22 -> 0.00047778309 | AB23: =C23 -> 0.0013157895 | AC23: =H23 -> 0.00086580087 | AD23: =M23 -> 0.0020920502 | AE23: =R23 -> -0.00017608734 | AF23: =D23 -> 343 | AG23: =I23 -> 80 | AH23: =N23 -> 896 | AI23: =S23 -> 447 | AJ23: =E23 -> 12 | AK23: =J23 -> 7 | AL23: =O23 -> 6 | AM23: =T23 -> 9 | AN23: =SUM(AJ23:AM23) -> 34 | AO23: =F23 -> 2 | AP23: =K23 -> 2 | AQ23: =P23 -> 2 | AR23: =U23 -> 2 | AS23: =SUM(AO23:AR23) -> 8
A24: 45964 | B24: 1526 | C24: =(B24-B23)/B23 -> 0.0026281209 | D24: 379 | E24: 6 | F24: 1 | G24: 2313 | H24: =(G24-G23)/G23 -> 0.00043252595 | I24: 35 | J24: 3 | K24: 1 | L24: 962 | M24: =(L24-L23)/L23 -> 0.0041753653 | N24: 775 | O24: 0 | P24: 1 | Q24: 5681 | R24: =(Q24-Q23)/Q23 -> 0.00052835505 | S24: 534 | T24: 9 | U24: 1 | V24: =B24 -> 1526 | W24: =G24 -> 2313 | X24: =L24 -> 962 | Y24: =Q24 -> 5681 | Z24: =SUM(V24:Y24) -> 10482 | AA24: =(Z24-Z23)/Z23 -> 0.0011461318 | AB24: =C24 -> 0.0026281209 | AC24: =H24 -> 0.00043252595 | AD24: =M24 -> 0.0041753653 | AE24: =R24 -> 0.00052835505 | AF24: =D24 -> 379 | AG24: =I24 -> 35 | AH24: =N24 -> 775 | AI24: =S24 -> 534 | AJ24: =E24 -> 6 | AK24: =J24 -> 3 | AL24: =O24 -> 0 | AM24: =T24 -> 9 | AN24: =SUM(AJ24:AM24) -> 18 | AO24: =F24 -> 1 | AP24: =K24 -> 1 | AQ24: =P24 -> 1 | AR24: =U24 -> 1 | AS24: =SUM(AO24:AR24) -> 4
A25: 45971 | B25: 1529 | C25: =(B25-B24)/B24 -> 0.001965924 | D25: 544 | E25: 7 | F25: 2 | G25: 2311 | H25: =(G25-G24)/G24 -> -0.00086467791 | I25: 102 | J25: 1 | K25: 2 | L25: 973 | M25: =(L25-L24)/L24 -> 0.011434511 | N25: 2079 | O25: 15 | P25: 2 | Q25: 5682 | R25: =(Q25-Q24)/Q24 -> 0.00017602535 | S25: 747 | T25: 25 | U25: 2 | V25: =B25 -> 1529 | W25: =G25 -> 2311 | X25: =L25 -> 973 | Y25: =Q25 -> 5682 | Z25: =SUM(V25:Y25) -> 10495 | AA25: =(Z25-Z24)/Z24 -> 0.0012402213 | AB25: =C25 -> 0.001965924 | AC25: =H25 -> -0.00086467791 | AD25: =M25 -> 0.011434511 | AE25: =R25 -> 0.00017602535 | AF25: =D25 -> 544 | AG25: =I25 -> 102 | AH25: =N25 -> 2079 | AI25: =S25 -> 747 | AJ25: =E25 -> 7 | AK25: =J25 -> 1 | AL25: =O25 -> 15 | AM25: =T25 -> 25 | AN25: =SUM(AJ25:AM25) -> 48 | AO25: =F25 -> 2 | AP25: =K25 -> 2 | AQ25: =P25 -> 2 | AR25: =U25 -> 2 | AS25: =SUM(AO25:AR25) -> 8
A26: 45978 | B26: 1533 | C26: =(B26-B25)/B25 -> 0.0026160889 | D26: 856 | E26: 18 | F26: 1 | G26: 2309 | H26: =(G26-G25)/G25 -> -0.00086542622 | I26: 82 | J26: 0 | K26: 1 | L26: 973 | M26: =(L26-L25)/L25 -> 0 | N26: 420 | O26: 2 | P26: 1 | Q26: 5678 | R26: =(Q26-Q25)/Q25 -> -0.00070397747 | S26: 333 | T26: 8 | U26: 1 | V26: =B26 -> 1533 | W26: =G26 -> 2309 | X26: =L26 -> 973 | Y26: =Q26 -> 5678 | Z26: =SUM(V26:Y26) -> 10493 | AA26: =(Z26-Z25)/Z25 -> -0.00019056694 | AB26: =C26 -> 0.0026160889 | AC26: =H26 -> -0.00086542622 | AD26: =M26 -> 0 | AE26: =R26 -> -0.00070397747 | AF26: =D26 -> 856 | AG26: =I26 -> 82 | AH26: =N26 -> 420 | AI26: =S26 -> 333 | AJ26: =E26 -> 18 | AK26: =J26 -> 0 | AL26: =O26 -> 2 | AM26: =T26 -> 8 | AN26: =SUM(AJ26:AM26) -> 28 | AO26: =F26 -> 1 | AP26: =K26 -> 1 | AQ26: =P26 -> 1 | AR26: =U26 -> 1 | AS26: =SUM(AO26:AR26) -> 4
A27: 45985 | B27: 1538 | C27: =(B27-B26)/B26 -> 0.0032615786 | D27: 477 | E27: 13 | F27: 1 | G27: 2309 | H27: =(G27-G26)/G26 -> 0 | I27: 68 | J27: 0 | K27: 1 | L27: 972 | M27: =(L27-L26)/L26 -> -0.0010277492 | N27: 770 | O27: 7 | P27: 1 | Q27: 5675 | R27: =(Q27-Q26)/Q26 -> -0.00052835505 | S27: 162 | T27: 4 | U27: 1 | V27: =B27 -> 1538 | W27: =G27 -> 2309 | X27: =L27 -> 972 | Y27: =Q27 -> 5675 | Z27: =SUM(V27:Y27) -> 10494 | AA27: =(Z27-Z26)/Z26 -> 9.530163e-05 | AB27: =C27 -> 0.0032615786 | AC27: =H27 -> 0 | AD27: =M27 -> -0.0010277492 | AE27: =R27 -> -0.00052835505 | AF27: =D27 -> 477 | AG27: =I27 -> 68 | AH27: =N27 -> 770 | AI27: =S27 -> 162 | AJ27: =E27 -> 13 | AK27: =J27 -> 0 | AL27: =O27 -> 7 | AM27: =T27 -> 4 | AN27: =SUM(AJ27:AM27) -> 24 | AO27: =F27 -> 1 | AP27: =K27 -> 1 | AQ27: =P27 -> 1 | AR27: =U27 -> 1 | AS27: =SUM(AO27:AR27) -> 4
A28: 45992 | B28: 1545 | C28: =(B28-B27)/B27 -> 0.0045513654 | D28: 340 | E28: 16 | F28: 1 | G28: 2309 | H28: =(G28-G27)/G27 -> 0 | I28: 206 | J28: 5 | K28: 1 | L28: 973 | M28: =(L28-L27)/L27 -> 0.0010288066 | N28: 768 | O28: 12 | P28: 1 | Q28: 5675 | R28: =(Q28-Q27)/Q27 -> 0 | S28: 344 | T28: 15 | U28: 1 | V28: =B28 -> 1545 | W28: =G28 -> 2309 | X28: =L28 -> 973 | Y28: =Q28 -> 5675 | Z28: =SUM(V28:Y28) -> 10502 | AA28: =(Z28-Z27)/Z27 -> 0.00076234038 | AB28: =C28 -> 0.0045513654 | AC28: =H28 -> 0 | AD28: =M28 -> 0.0010288066 | AE28: =R28 -> 0 | AF28: =D28 -> 340 | AG28: =I28 -> 206 | AH28: =N28 -> 768 | AI28: =S28 -> 344 | AJ28: =E28 -> 16 | AK28: =J28 -> 5 | AL28: =O28 -> 12 | AM28: =T28 -> 15 | AN28: =SUM(AJ28:AM28) -> 48 | AO28: =F28 -> 1 | AP28: =K28 -> 1 | AQ28: =P28 -> 1 | AR28: =U28 -> 1 | AS28: =SUM(AO28:AR28) -> 4
A29: 45999 | B29: 1551 | C29: =(B29-B28)/B28 -> 0.0038834951 | D29: 480 | E29: 22 | F29: 1 | G29: 2308 | H29: =(G29-G28)/G28 -> -0.00043308792 | I29: 63 | J29: 3 | K29: 1 | L29: 975 | M29: =(L29-L28)/L28 -> 0.0020554985 | N29: 366 | O29: 11 | P29: 1 | Q29: 5677 | R29: =(Q29-Q28)/Q28 -> 0.00035242291 | S29: 242 | T29: 12 | U29: 1 | V29: =B29 -> 1551 | W29: =G29 -> 2308 | X29: =L29 -> 975 | Y29: =Q29 -> 5677 | Z29: =SUM(V29:Y29) -> 10511 | AA29: =(Z29-Z28)/Z28 -> 0.00085697962 | AB29: =C29 -> 0.0038834951 | AC29: =H29 -> -0.00043308792 | AD29: =M29 -> 0.0020554985 | AE29: =R29 -> 0.00035242291 | AF29: =D29 -> 480 | AG29: =I29 -> 63 | AH29: =N29 -> 366 | AI29: =S29 -> 242 | AJ29: =E29 -> 22 | AK29: =J29 -> 3 | AL29: =O29 -> 11 | AM29: =T29 -> 12 | AN29: =SUM(AJ29:AM29) -> 48 | AO29: =F29 -> 1 | AP29: =K29 -> 1 | AQ29: =P29 -> 1 | AR29: =U29 -> 1 | AS29: =SUM(AO29:AR29) -> 4
A30: 46006 | B30: 1558 | C30: =(B30-B29)/B29 -> 0.0045132173 | D30: 420 | E30: 17 | F30: 1 | G30: 2307 | H30: =(G30-G29)/G29 -> -0.00043327556 | I30: 68 | J30: 2 | K30: 1 | L30: 976 | M30: =(L30-L29)/L29 -> 0.001025641 | N30: 337 | O30: 3 | P30: 1 | Q30: 5681 | R30: =(Q30-Q29)/Q29 -> 0.0007045975 | S30: 298 | T30: 9 | U30: 1 | V30: =B30 -> 1558 | W30: =G30 -> 2307 | X30: =L30 -> 976 | Y30: =Q30 -> 5681 | Z30: =SUM(V30:Y30) -> 10522 | AA30: =(Z30-Z29)/Z29 -> 0.0010465227 | AB30: =C30 -> 0.0045132173 | AC30: =H30 -> -0.00043327556 | AD30: =M30 -> 0.001025641 | AE30: =R30 -> 0.0007045975 | AF30: =D30 -> 420 | AG30: =I30 -> 68 | AH30: =N30 -> 337 | AI30: =S30 -> 298 | AJ30: =E30 -> 17 | AK30: =J30 -> 2 | AL30: =O30 -> 3 | AM30: =T30 -> 9 | AN30: =SUM(AJ30:AM30) -> 31 | AO30: =F30 -> 1 | AP30: =K30 -> 1 | AQ30: =P30 -> 1 | AR30: =U30 -> 1 | AS30: =SUM(AO30:AR30) -> 4
A31: 46013 | B31: 1563 | C31: =(B31-B30)/B30 -> 0.0032092426 | D31: 472 | E31: 10 | F31: 0 | G31: 2305 | H31: =(G31-G30)/G30 -> -0.00086692674 | I31: 20 | J31: 0 | K31: 0 | L31: 981 | M31: =(L31-L30)/L30 -> 0.0051229508 | N31: 496 | O31: 6 | P31: 0 | Q31: 5679 | R31: =(Q31-Q30)/Q30 -> -0.0003520507 | S31: 115 | T31: 0 | U31: 0 | V31: =B31 -> 1563 | W31: =G31 -> 2305 | X31: =L31 -> 981 | Y31: =Q31 -> 5679 | Z31: =SUM(V31:Y31) -> 10528 | AA31: =(Z31-Z30)/Z30 -> 0.0005702338 | AB31: =C31 -> 0.0032092426 | AC31: =H31 -> -0.00086692674 | AD31: =M31 -> 0.0051229508 | AE31: =R31 -> -0.0003520507 | AF31: =D31 -> 472 | AG31: =I31 -> 20 | AH31: =N31 -> 496 | AI31: =S31 -> 115 | AJ31: =E31 -> 10 | AK31: =J31 -> 0 | AL31: =N31 -> 496 | AM31: =T31 -> 0 | AN31: =SUM(AJ31:AM31) -> 506 | AO31: =F31 -> 0 | AP31: =K31 -> 0 | AQ31: =P31 -> 0 | AR31: =U31 -> 0 | AS31: =SUM(AO31:AR31) -> 0
A32: 46020 | B32: 1567 | C32: =(B32-B31)/B31 -> 0.0025591811 | D32: 294 | E32: 6 | F32: 0 | G32: 2307 | H32: =(G32-G31)/G31 -> 0.00086767896 | I32: 11 | J32: 0 | K32: 0 | L32: 981 | M32: =(L32-L31)/L31 -> 0 | N32: 78 | O32: 0 | P32: 0 | Q32: 5680 | R32: =(Q32-Q31)/Q31 -> 0.00017608734 | S32: 34 | T32: 3 | U32: 0 | V32: =B32 -> 1567 | W32: =G32 -> 2307 | X32: =L32 -> 981 | Y32: =Q32 -> 5680 | Z32: =SUM(V32:Y32) -> 10535 | AA32: =(Z32-Z31)/Z31 -> 0.00066489362 | AB32: =C32 -> 0.0025591811 | AC32: =H32 -> 0.00086767896 | AD32: =M32 -> 0 | AE32: =R32 -> 0.00017608734 | AF32: =D32 -> 294 | AG32: =I32 -> 11 | AH32: =N32 -> 78 | AI32: =S32 -> 34 | AJ32: =E32 -> 6 | AK32: =J32 -> 0 | AL32: =O32 -> 0 | AM32: =T32 -> 3 | AN32: =SUM(AJ32:AM32) -> 9 | AO32: =F32 -> 0 | AP32: =K32 -> 0 | AQ32: =P33 -> 0 | AR32: =U32 -> 0 | AS32: =SUM(AO32:AR32) -> 0
A33: 46027 | B33: 1568 | C33: =(B33-B32)/B32 -> 0.00063816209 | D33: 356 | E33: 6 | F33: 0 | G33: 2308 | H33: =(G33-G32)/G32 -> 0.00043346337 | I33: 39 | J33: 0 | K33: 0 | L33: 982 | M33: =(L33-L32)/L32 -> 0.001019368 | N33: 63 | O33: 1 | P33: 0 | Q33: 5678 | R33: =(Q33-Q32)/Q32 -> -0.00035211268 | S33: 69 | T33: 4 | U33: 0 | V33: =B33 -> 1568 | W33: =G33 -> 2308 | X33: =L33 -> 982 | Y33: =Q33 -> 5678 | Z33: =SUM(V33:Y33) -> 10536 | AA33: =(Z33-Z32)/Z32 -> 9.492169e-05 | AB33: =C33 -> 0.00063816209 | AC33: =H33 -> 0.00043346337 | AD33: =M33 -> 0.001019368 | AE33: =R33 -> -0.00035211268 | AF33: =D33 -> 356 | AG33: =I33 -> 39 | AH33: =N33 -> 63 | AI33: =S33 -> 69 | AJ33: =E33 -> 6 | AK33: =J33 -> 0 | AL33: =O33 -> 1 | AM33: =T33 -> 4 | AN33: =SUM(AJ33:AM33) -> 11 | AO33: =F33 -> 0 | AP33: =K33 -> 0 | AQ33: =#REF! -> #REF! | AR33: =U33 -> 0 | AS33: =SUM(AO33:AR33) -> #REF!
A34: 46034 | B34: 1568 | C34: =(B34-B33)/B33 -> 0 | D34: 348 | E34: 8 | F34: 1 | G34: 2309 | H34: =(G34-G33)/G33 -> 0.00043327556 | I34: 100 | J34: 2 | K34: 1 | L34: 983 | M34: =(L34-L33)/L33 -> 0.0010183299 | N34: 313 | O34: 3 | P34: 1 | Q34: 5678 | R34: =(Q34-Q33)/Q33 -> 0 | S34: 301 | T34: 7 | U34: 1 | V34: =B34 -> 1568 | W34: =G34 -> 2309 | X34: =L34 -> 983 | Y34: =Q34 -> 5678 | Z34: =SUM(V34:Y34) -> 10538 | AA34: =(Z34-Z33)/Z33 -> 0.00018982536 | AB34: =C34 -> 0 | AC34: =H34 -> 0.00043327556 | AD34: =M34 -> 0.0010183299 | AE34: =R34 -> 0 | AF34: =D34 -> 348 | AG34: =I34 -> 100 | AH34: =N34 -> 313 | AI34: =S34 -> 301 | AJ34: =E34 -> 8 | AK34: =J34 -> 2 | AL34: =O34 -> 3 | AM34: =T34 -> 7 | AN34: =SUM(AJ34:AM34) -> 20 | AO34: =F34 -> 1 | AP34: =K34 -> 1 | AQ34: =P34 -> 1 | AR34: =U34 -> 1 | AS34: =SUM(AO34:AR34) -> 4
A35: 46041 | B35: 1568 | C35: =(B35-B34)/B34 -> 0 | D35: 100 | E35: 1 | F35: 0 | G35: 2309 | H35: =(G35-G34)/G34 -> 0 | I35: 21 | J35: 0 | K35: 0 | L35: 983 | M35: =(L35-L34)/L34 -> 0 | N35: 92 | O35: 2 | P35: 0 | Q35: 5681 | R35: =(Q35-Q34)/Q34 -> 0.00052835505 | S35: 82 | T35: 0 | U35: 0 | V35: =B35 -> 1568 | W35: =G35 -> 2309 | X35: =L35 -> 983 | Y35: =Q35 -> 5681 | Z35: =SUM(V35:Y35) -> 10541 | AA35: =(Z35-Z34)/Z34 -> 0.000284684 | AB35: =C35 -> 0 | AC35: =H35 -> 0 | AD35: =M35 -> 0 | AE35: =R35 -> 0.00052835505 | AF35: =D35 -> 100 | AG35: =I35 -> 21 | AH35: =N35 -> 92 | AI35: =S35 -> 82 | AJ35: =E35 -> 1 | AK35: =J35 -> 0 | AL35: =O35 -> 2 | AM35: =T35 -> 0 | AN35: =SUM(AJ35:AM35) -> 3 | AO35: =F35 -> 0 | AP35: =K35 -> 0 | AQ35: =P35 -> 0 | AR35: =U35 -> 0 | AS35: =SUM(AO35:AR35) -> 0
A36: 46048 | B36: 1575 | C36: =(B36-B35)/B35 -> 0.0044642857 | D36: 292 | E36: 17 | F36: 1 | G36: 2315 | H36: =(G36-G35)/G35 -> 0.0025985275 | I36: 261 | J36: 2 | K36: 1 | L36: 987 | M36: =(L36-L35)/L35 -> 0.004069176 | N36: 325 | O36: 3 | P36: 1 | Q36: 5684 | R36: =(Q36-Q35)/Q35 -> 0.00052807604 | S36: 544 | T36: 32 | U36: 1 | V36: =B36 -> 1575 | W36: =G36 -> 2315 | X36: =L36 -> 987 | Y36: =Q36 -> 5684 | Z36: =SUM(V36:Y36) -> 10561 | AA36: =(Z36-Z35)/Z35 -> 0.0018973532 | AB36: =C36 -> 0.0044642857 | AC36: =H36 -> 0.0025985275 | AD36: =M36 -> 0.004069176 | AE36: =R36 -> 0.00052807604 | AF36: =D36 -> 292 | AG36: =I36 -> 261 | AH36: =N36 -> 325 | AI36: =S36 -> 544 | AJ36: =E36 -> 17 | AK36: =J36 -> 2 | AL36: =O36 -> 3 | AM36: =T36 -> 32 | AN36: =SUM(AJ36:AM36) -> 54 | AO36: =F36 -> 1 | AP36: =K36 -> 1 | AQ36: =P36 -> 1 | AR36: =U36 -> 1 | AS36: =SUM(AO36:AR36) -> 4
